<?xml version="1.0"?>
<robot name="origins" xmlns:xacro="http://www.ros.org/wiki/xacro">

    <!-- Import all Gazebo-customization elements, including Gazebo colors -->
    <xacro:include filename="$(find third_robot_description)/urdf/third_robot.gazebo" />
    <xacro:include filename="$(find third_robot_description)/urdf/third_robot_macro.xacro" />

    <link name="base_link">
        <visual>
            <origin rpy="0 0 0" xyz="0 0 0.55" />
            <geometry>
                <mesh filename="package://third_robot_description/meshes/third_robot/third_robot_body.dae"/>
            </geometry>
        </visual>
        <collision>
            <origin rpy="0 0 0" xyz="0 0 0.35" />
            <geometry>
                <box size="1.05 0.55 0.4"/>
            </geometry>
        </collision>
        <xacro:default_inertial mass="10"/>
    </link>

    <xacro:wheel right_left="right" reflect="1"/>

    <xacro:wheel right_left="left" reflect="-1"/>

    <link name="right_rear_wheel">
        <visual>
            <origin rpy="0 0 0" xyz="0 0 0"/>
            <geometry>
                <mesh filename="package://third_robot_description/meshes/third_robot/third_robot_wheel.dae"/>
            </geometry>
        </visual>
        <collision>
            <origin rpy="${PI/2} 0 0" xyz="0 0 0"/>
            <geometry>
                <cylinder length="${length_wheel}" radius="${radius_wheel}"/>
            </geometry>
        </collision>
        <xacro:default_inertial mass="1"/>
    </link>

    <joint name="base_to_right_rear_wheel" type="continuous">
        <axis xyz="0 1 0"/>
        <parent link="base_link"/>
        <child link="right_rear_wheel"/>
        <origin xyz="-0.38 -${length_from_base_to_wheel_y} ${radius_wheel}"/>
    </joint>

    <link name="left_rear_wheel">
        <visual>
            <origin rpy="${PI} 0 0" xyz="0 0 0"/>
            <geometry>
                <mesh filename="package://third_robot_description/meshes/third_robot/third_robot_wheel.dae"/>
            </geometry>
        </visual>
        <collision>
            <origin rpy="${PI/2} 0 0" xyz="0 0 0"/>
            <geometry>
                <cylinder length="${length_wheel}" radius="${radius_wheel}"/>
            </geometry>
        </collision>
        <xacro:default_inertial mass="1"/>
    </link>

    <joint name="base_to_left_rear_wheel" type="continuous">
        <axis xyz="0 1 0"/>
        <parent link="base_link"/>
        <child link="left_rear_wheel"/>
        <origin xyz="-0.38 ${length_from_base_to_wheel_y} ${radius_wheel}"/>
    </joint>

    <link name="front_top_lrf">
        <visual>
            <origin rpy="0 0.5 0" xyz="0 0 0"/>
            <geometry>
                <mesh filename="package://third_robot_description/meshes/LRF/UTM-30LX.dae"/>
            </geometry>
        </visual>
    </link>

    <joint name="base_to_front_top_lrf" type="fixed">
        <axis xyz="0 1 0"/>
        <parent link="base_link"/>
        <child link="front_top_lrf"/>
        <origin rpy="0 0.53 0" xyz="0.40 0 0.75"/>
    </joint>

    <link name="front_bottom_lrf">
        <visual>
            <origin rpy="0 0 0" xyz="0 0 0"/>
            <geometry>
                <mesh filename="package://third_robot_description/meshes/LRF/UTM-30LX.dae"/>
            </geometry>
        </visual>
    </link>

    <joint name="base_to_front_bottom_lrf" type="fixed">
        <axis xyz="0 1 0"/>
        <parent link="base_link"/>
        <child link="front_bottom_lrf"/>
        <origin xyz="0.50 0 0.39"/>
    </joint>

    <link name="rear_bottom_lrf">
        <visual>
            <origin rpy="0 0 ${PI}" xyz="0 0 0"/>
            <geometry>
                <mesh filename="package://third_robot_description/meshes/LRF/UTM-30LX.dae"/>
            </geometry>
        </visual>
    </link>

    <joint name="base_to_rear_bottom_lrf" type="fixed">
        <axis xyz="0 1 0"/>
        <parent link="base_link"/>
        <child link="rear_bottom_lrf"/>
        <origin xyz="-0.45 0 0.35"/>
    </joint>
<!--
    <transmission name="tran1">
        <type>transmission_interface/SimpleTransmission</type>
        <joint name="base_to_left_rear_wheel">
            <hardwareInterface>EffortJointInterface</hardwareInterface>
        </joint>
        <actuator name="motor1">
            <hardwareInterface>EffortJointInterface</hardwareInterface>
            <mechanicalReduction>1</mechanicalReduction>
        </actuator>
    </transmission>

    <transmission name="tran2">
        <type>transmission_interface/SimpleTransmission</type>
        <joint name="base_to_right_rear_wheel">
            <hardwareInterface>EffortJointInterface</hardwareInterface>
        </joint>
        <actuator name="motor2">
            <hardwareInterface>EffortJointInterface</hardwareInterface>
            <mechanicalReduction>1</mechanicalReduction>
        </actuator>
    </transmission>
-->
</robot>
