<?xml version="1.0"?>
<robot name="origins" xmlns:xacro="http://www.ros.org/wiki/xacro">
    <!-- Constants for math -->
    <xacro:property name="PI" value="3.1415926535897931" />
    <!-- Constants for robot dimensions -->
    <xacro:property name="length_wheel" value="0.07" />
    <xacro:property name="radius_wheel" value="0.14" />
    <xacro:property name="length_from_base_to_wheel_front_x" value="0.41" />
    <xacro:property name="length_from_base_to_wheel_y" value="0.25" />
    <xacro:macro name="default_inertial" params="mass">
        <inertial>
            <mass value="${mass}" />
            <inertia ixx="1.0" ixy="0.0" ixz="0.0"
                iyy="1.0" iyz="0.0"
                izz="1.0" />
        </inertial>
    </xacro:macro>
    <xacro:macro name="wheel" params="right_left reflect">
        <link name="${right_left}_front_wheel">
            <visual>
                <!-- when reflect = 1 to be 0 reflect= -1 to be PI -->
                <origin rpy="${PI/2-reflect*PI/2} 0 0" xyz="0 0 0"/>
                <!-- <origin rpy="${PI/2-reflect*PI/2} 0 0" xyz="0 0 0"/> -->
                <geometry>
                    <mesh filename="package://third_robot_description/meshes/third_robot/third_robot_wheel.dae"/>
                </geometry>
                ->
            </visual>
            <collision>
                <origin rpy="${PI/2} 0 0" xyz="0 0 0"/>
                <geometry>
                    <cylinder length="${length_wheel}" radius="${radius_wheel}"/>
                </geometry>
            </collision>
            <xacro:default_inertial mass="1"/>
        </link>
        <joint name="base_to_${right_left}_front_wheel" type="continuous">
            <axis xyz="0 1 0"/>
            <parent link="base_link"/>
            <child link="${right_left}_front_wheel"/>
            <origin xyz="${length_from_base_to_wheel_front_x} ${-reflect*length_from_base_to_wheel_y} ${radius_wheel}"/>
        </joint>
    </xacro:macro>
</robot>

